<?xml version="1.0"?>
<robot xmlns:xacro="http://www.ros.org/wiki/xacro" name="twin">
    <material name="gray">
        <color rgba="0.5 0.5 0.5 1"/>
    </material>
    <material name="white">
        <color rgba="1 1 1 1"/>
    </material>
    <material name="black">
        <color rgba="0 0 0 1"/>
    </material>
    <material name="red">
        <color rgba="1 0 0 1"/>
    </material>
    <material name="green">
        <color rgba="0 1 0 1"/>
    </material>
    <material name="blue">
        <color rgba="0 0 1 1"/>
    </material>
    <material name="yellow">
        <color rgba="1 1 0 1"/>
    </material>
    <material name="cyan">
        <color rgba="0 1 1 1"/>
    </material>
    <material name="magenta">
        <color rgba="1 0 1 1"/>
    </material>

    <link name="world"> </link>
    <joint name="world_to_table" type="fixed">
        <origin xyz="1 0 0" rpy="0 0 0"/>
        <parent link="world"/>
        <child link="table"/>
    </joint>

    <link name="table">
        <visual>
            <origin xyz="0 0 0" rpy="0 0 0"/>
            <geometry>
                <box size="2 2 0.1"/>
            </geometry>
            <material name="gray"/>
        </visual>
        <collision>
            <origin xyz="1 0 0" rpy="0 0 0"/>
            <geometry>
                <box size="2 2 0.1"/>
            </geometry>
        </collision>
    </link>

    <!-- Joint for stacking the floors vertically and allowing horizontal movement -->
    <joint name="table_to_firstFloor" type="prismatic">
        <origin xyz="0 0 0.1" rpy="0 0 0"/> <!-- Positioning first floor directly on the table -->
        <parent link="table"/>
        <child link="firstFloor"/>
        <axis xyz="1 0 0"/> <!-- Horizontal movement along the x-axis -->
        <limit lower="-0.1" upper="0.1" effort="1000" velocity="1.0"/>
    </joint>

    <link name="firstFloor">
        <visual>
            <origin xyz="0 0 1" rpy="0 0 0"/>
            <geometry>
                <box size="1 1 2"/>
            </geometry>
            <material name="red"/> <!-- Color changed to red -->
        </visual>
        <collision>
            <origin xyz="0 0 0" rpy="0 0 0"/>
            <geometry>
                <box size="1 1 2"/>
            </geometry>
        </collision>
    </link>

    <!-- Joint for placing second floor on top of first floor, horizontal movement -->
    <joint name="firstFloor_to_secondFloor" type="prismatic">
        <origin xyz="0 0 2" rpy="0 0 0"/> <!-- Placing second floor above the first floor -->
        <parent link="firstFloor"/>
        <child link="secondFloor"/>
        <axis xyz="1 0 0"/> <!-- Horizontal movement along the x-axis -->
        <limit lower="-0.1" upper="0.1" effort="1000" velocity="1.0"/>
    </joint>

    <link name="secondFloor">
        <visual>
            <origin xyz="0 0 1" rpy="0 0 0"/>
            <geometry>
                <box size="1 1 2"/>
            </geometry>
            <material name="green"/> <!-- Color changed to green -->
        </visual>
        <collision>
            <origin xyz="0 0 1" rpy="0 0 0"/>
            <geometry>
                <box size="1 1 2"/>
            </geometry>
        </collision>
    </link>

    <!-- Joint for placing third floor on top of second floor, horizontal movement -->
    <joint name="secondFloor_to_thirdFloor" type="prismatic">
        <origin xyz="0 0 2" rpy="0 0 0"/> <!-- Placing third floor above the second floor -->
        <parent link="secondFloor"/>
        <child link="thirdFloor"/>
        <axis xyz="1 0 0"/> <!-- Horizontal movement along the x-axis -->
        <limit lower="-0.1" upper="0.1" effort="1000" velocity="1.0"/>
    </joint>

    <link name="thirdFloor">
        <visual>
            <origin xyz="0 0 1" rpy="0 0 0"/>
            <geometry>
                <box size="1 1 2"/>
            </geometry>
            <material name="blue"/> <!-- Color changed to blue -->
        </visual>
        <collision>
            <origin xyz="0 0 1" rpy="0 0 0"/>
            <geometry>
                <box size="1 1 2"/>
            </geometry>
        </collision>
    </link>

    <!-- Joint for placing fourth floor on top of third floor, horizontal movement -->
    <joint name="thirdFloor_to_fourthFloor" type="prismatic">
        <origin xyz="0 0 2" rpy="0 0 0"/> <!-- Placing fourth floor above the third floor -->
        <parent link="thirdFloor"/>
        <child link="fourthFloor"/>
        <axis xyz="1 0 0"/> <!-- Horizontal movement along the x-axis -->
        <limit lower="-0.1" upper="0.1" effort="1000" velocity="1.0"/>
    </joint>

    <link name="fourthFloor">
        <visual>
            <origin xyz="0 0 1" rpy="0 0 0"/>
            <geometry>
                <box size="1 1  2"/>
            </geometry>
            <material name="yellow"/> <!-- Color changed to yellow -->
        </visual>
        <collision>
            <origin xyz="0 0 0" rpy="0 0 0"/>
            <geometry>
                <box size="1 1 2"/>
            </geometry>
        </collision>
    </link>

    <!-- Joint for placing fifth floor on top of fourth floor, horizontal movement -->
    <joint name="fourthFloor_to_fifthFloor" type="prismatic">
        <origin xyz="0 0 2" rpy="0 0 0"/> <!-- Placing fifth floor above the fourth floor -->
        <parent link="fourthFloor"/>
        <child link="fifthFloor"/>
        <axis xyz="1 0 0"/> <!-- Horizontal movement along the x-axis -->
        <limit lower="-0.1" upper="0.1" effort="1000" velocity="1.0"/>
    </joint>

    <link name="fifthFloor">
        <visual>
            <origin xyz="0 0 1" rpy="0 0 0"/>
            <geometry>
                <box size="1 1 2 "/>
            </geometry>
            <material name="cyan"/> <!-- Color changed to cyan -->
        </visual>
        <collision>
            <origin xyz="0 0 0" rpy="0 0 0"/>
            <geometry>
                <box size="1 1 2"/>
            </geometry>
        </collision>
    </link>

    <joint name="world_to_camera" type="fixed">
        <parent link="world"/>
        <child link="camera"/>
        <origin xyz="1 1 0" rpy="0 0 0"/>
    </joint>
    <link name="camera">
        <visual>
            <origin xyz="0 0 0" rpy="0 0 0"/>
            <geometry>
                <box size="0.1 0.1 0.1"/>
            </geometry>
            <material name="red"/>
        </visual>
        <collision>
            <origin xyz="0 0 0" rpy="0 0 0"/>
            <geometry>
                <box size="0.1 0.1 0.1"/>
            </geometry>
        </collision>
    </link>
</robot>
